pyxis: importing docker image: doduo1.umcn.nl#tabea/spliceai:2.3
pyxis: imported docker image: doduo1.umcn.nl#tabea/spliceai:2.3
Traceback (most recent call last):
  File "/home/scripts/train_model.py", line 206, in <module>
    X = h5f['X' + str(idx)][:]
  File "h5py/_objects.pyx", line 54, in h5py._objects.with_phil.wrapper
  File "h5py/_objects.pyx", line 55, in h5py._objects.with_phil.wrapper
  File "/usr/local/lib/python3.9/site-packages/h5py/_hl/group.py", line 305, in __getitem__
    oid = h5o.open(self.id, self._e(name), lapl=self._lapl)
  File "h5py/_objects.pyx", line 54, in h5py._objects.with_phil.wrapper
  File "h5py/_objects.pyx", line 55, in h5py._objects.with_phil.wrapper
  File "h5py/h5o.pyx", line 190, in h5py.h5o.open
KeyError: "Unable to open object (file read failed: time = Fri Jun 28 08:16:57 2024\n, filename = '/data/retina_train_all.h5', file descriptor = 35, errno = 112, error message = 'Host is down', buf = 0x7f2ad00118f0, total read size = 512, bytes this sub-read = 512, bytes actually read = 18446744073709551615, offset = 0)"
