pyxis: importing docker image: doduo1.umcn.nl#tabea/spliceai:2.3
pyxis: imported docker image: doduo1.umcn.nl#tabea/spliceai:2.3
Traceback (most recent call last):
  File "/home/scripts/train_model.py", line 206, in <module>
    X = h5f['X' + str(idx)][:]
  File "h5py/_objects.pyx", line 54, in h5py._objects.with_phil.wrapper
  File "h5py/_objects.pyx", line 55, in h5py._objects.with_phil.wrapper
  File "/usr/local/lib/python3.9/site-packages/h5py/_hl/dataset.py", line 710, in __getitem__
    return self._fast_reader.read(args)
  File "h5py/_selector.pyx", line 366, in h5py._selector.Reader.read
OSError: [Errno 112] Can't read data (file read failed: time = Fri Jun 28 08:16:57 2024
, filename = '/data/retina_train_all.h5', file descriptor = 35, errno = 112, error message = 'Host is down', buf = 0x7f4f7f642010, total read size = 66360000, bytes this sub-read = 66360000, bytes actually read = 18446744073709551615, offset = 0)
Traceback (most recent call last):
  File "/home/scripts/train_model.py", line 169, in <module>
    h5f = h5py.File('/data/' + dataset + '_train_all.h5')
  File "/usr/local/lib/python3.9/site-packages/h5py/_hl/files.py", line 507, in __init__
    fid = make_fid(name, mode, userblock_size, fapl, fcpl, swmr=swmr)
  File "/usr/local/lib/python3.9/site-packages/h5py/_hl/files.py", line 220, in make_fid
    fid = h5f.open(name, flags, fapl=fapl)
  File "h5py/_objects.pyx", line 54, in h5py._objects.with_phil.wrapper
  File "h5py/_objects.pyx", line 55, in h5py._objects.with_phil.wrapper
  File "h5py/h5f.pyx", line 106, in h5py.h5f.open
OSError: [Errno 112] Unable to open file (unable to open file: name = '/data/retina_train_all.h5', errno = 112, error message = 'Host is down', flags = 0, o_flags = 0)
